Upstream: Yes
Reason: Python 3.8 test failure

URL: https://github.com/pytest-dev/pytest-xdist/pull/527
--- a/testing/acceptance_test.py
+++ b/testing/acceptance_test.py
@@ -115,9 +115,7 @@ class TestDistribution:
         assert result.ret == 2
         result.stdout.fnmatch_lines(["*Interrupted: stopping*1*", "*1 failed*"])
 
-    @pytest.mark.xfail(
-        reason="#527: Python 3.8 failure in pytest where testdir.tmpdir returns an unexpected value"
-    )
+    @pytest.mark.skip(reason="failure")
     def test_basetemp_in_subprocesses(self, testdir):
         p1 = testdir.makepyfile(
             """
